Traceback (most recent call last):
  File "/scratch1/07169/wgl/adjoint/python/Main_no_matrix.py", line 149, in <module>
    params = net.init(rng, jnp.ones(1), jnp.ones(1), jnp.ones(1))
  File "/work2/07169/wgl/frontera/PHO-ICES/adj-env/lib/python3.9/site-packages/jax/_src/traceback_util.py", line 166, in reraise_with_filtered_traceback
    return fun(*args, **kwargs)
  File "/work2/07169/wgl/frontera/PHO-ICES/adj-env/lib/python3.9/site-packages/flax/linen/module.py", line 1621, in init
    _, v_out = self.init_with_output(
  File "/work2/07169/wgl/frontera/PHO-ICES/adj-env/lib/python3.9/site-packages/jax/_src/traceback_util.py", line 166, in reraise_with_filtered_traceback
    return fun(*args, **kwargs)
  File "/work2/07169/wgl/frontera/PHO-ICES/adj-env/lib/python3.9/site-packages/flax/linen/module.py", line 1526, in init_with_output
    return init_with_output(
  File "/work2/07169/wgl/frontera/PHO-ICES/adj-env/lib/python3.9/site-packages/flax/core/scope.py", line 965, in wrapper
    return apply(fn, mutable=mutable, flags=init_flags)({}, *args, rngs=rngs,
  File "/work2/07169/wgl/frontera/PHO-ICES/adj-env/lib/python3.9/site-packages/flax/core/scope.py", line 933, in wrapper
    y = fn(root, *args, **kwargs)
  File "/work2/07169/wgl/frontera/PHO-ICES/adj-env/lib/python3.9/site-packages/flax/linen/module.py", line 2102, in scope_fn
    return fn(module.clone(parent=scope), *args, **kwargs)
  File "/work2/07169/wgl/frontera/PHO-ICES/adj-env/lib/python3.9/site-packages/flax/linen/module.py", line 427, in wrapped_module_method
    return self._call_wrapped_method(fun, args, kwargs)
  File "/work2/07169/wgl/frontera/PHO-ICES/adj-env/lib/python3.9/site-packages/flax/linen/module.py", line 845, in _call_wrapped_method
    y = fun(self, *args, **kwargs)
  File "/scratch1/07169/wgl/adjoint/python/models.py", line 17, in __call__
    for size in self.feature_sizes:
jax._src.traceback_util.UnfilteredStackTrace: TypeError: 'int' object is not iterable
The stack trace below excludes JAX-internal frames.
The preceding is the original exception that occurred, unmodified.
--------------------
The above exception was the direct cause of the following exception:
Traceback (most recent call last):
  File "/scratch1/07169/wgl/adjoint/python/Main_no_matrix.py", line 149, in <module>
    params = net.init(rng, jnp.ones(1), jnp.ones(1), jnp.ones(1))
  File "/scratch1/07169/wgl/adjoint/python/models.py", line 17, in __call__
    for size in self.feature_sizes:
TypeError: 'int' object is not iterable