> /scratch/07169/wgl/adjoint/python/Main_no_matrix.py(61)sumTerm()
-> return (grad(lambda u, t, dt, p, n: forwardFn(u, t, dt, p, n)[0])(u_prev,
Array(1.5431181, dtype=float32)
> /scratch/07169/wgl/adjoint/python/Main_no_matrix.py(62)sumTerm()
-> t_prev,
> /scratch/07169/wgl/adjoint/python/Main_no_matrix.py(63)sumTerm()
-> dt_j,
> /scratch/07169/wgl/adjoint/python/Main_no_matrix.py(64)sumTerm()
-> params,
> /scratch/07169/wgl/adjoint/python/Main_no_matrix.py(65)sumTerm()
-> net))[i]
> /scratch/07169/wgl/adjoint/python/Main_no_matrix.py(61)sumTerm()
-> return (grad(lambda u, t, dt, p, n: forwardFn(u, t, dt, p, n)[0])(u_prev,
> /scratch/07169/wgl/adjoint/python/Main_no_matrix.py(61)<lambda>()
-> return (grad(lambda u, t, dt, p, n: forwardFn(u, t, dt, p, n)[0])(u_prev,
--Return--
> /scratch/07169/wgl/adjoint/python/Main_no_matrix.py(61)<lambda>()->Traced<Concre...me='jvp'),))))
-> return (grad(lambda u, t, dt, p, n: forwardFn(u, t, dt, p, n)[0])(u_prev,
--Call--
> /work/07169/wgl/ls6/PHO-ICES/adj-env/lib/python3.9/site-packages/jax/_src/api_util.py(322)_argnums_partial()
-> ans = yield args, kwargs
> /work/07169/wgl/ls6/PHO-ICES/adj-env/lib/python3.9/site-packages/jax/_src/api_util.py(323)_argnums_partial()
-> yield ans
*** NameError: name 'nn' is not defined
*** NameError: name 'nn' is not defined
*** NameError: name 'nn' is not defined
GeneratorExit
> /work/07169/wgl/ls6/PHO-ICES/adj-env/lib/python3.9/site-packages/jax/_src/api_util.py(323)_argnums_partial()
-> yield ans
> /scratch/07169/wgl/adjoint/python/Main_no_matrix.py(61)sumTerm()
-> return (grad(lambda u, t, dt, p, n: forwardFn(u, t, dt, p, n)[0])(u_prev,
--Return--
> /scratch/07169/wgl/adjoint/python/Main_no_matrix.py(61)sumTerm()->Array(1.01156...dtype=float32)
-> return (grad(lambda u, t, dt, p, n: forwardFn(u, t, dt, p, n)[0])(u_prev,
--Call--
> /work/07169/wgl/ls6/PHO-ICES/adj-env/lib/python3.9/site-packages/jax/_src/numpy/array_methods.py(246)deferring_binary_op()
-> def deferring_binary_op(self, other):
> /work/07169/wgl/ls6/PHO-ICES/adj-env/lib/python3.9/site-packages/jax/_src/numpy/array_methods.py(247)deferring_binary_op()
-> if hasattr(other, '__jax_array__'):
> /work/07169/wgl/ls6/PHO-ICES/adj-env/lib/python3.9/site-packages/jax/_src/numpy/array_methods.py(249)deferring_binary_op()
-> args = (other, self) if swap else (self, other)
> /work/07169/wgl/ls6/PHO-ICES/adj-env/lib/python3.9/site-packages/jax/_src/numpy/array_methods.py(250)deferring_binary_op()
-> if isinstance(other, _accepted_binop_types):
*** NameError: name 'nn' is not defined
> /work/07169/wgl/ls6/PHO-ICES/adj-env/lib/python3.9/site-packages/jax/_src/numpy/array_methods.py(251)deferring_binary_op()
-> return binary_op(*args)
> /scratch/07169/wgl/adjoint/python/Main_no_matrix.py(61)sumTerm()
-> return (grad(lambda u, t, dt, p, n: forwardFn(u, t, dt, p, n)[0])(u_prev,
> /scratch/07169/wgl/adjoint/python/Main_no_matrix.py(61)sumTerm()
-> return (grad(lambda u, t, dt, p, n: forwardFn(u, t, dt, p, n)[0])(u_prev,
> /scratch/07169/wgl/adjoint/python/Main_no_matrix.py(61)<lambda>()
-> return (grad(lambda u, t, dt, p, n: forwardFn(u, t, dt, p, n)[0])(u_prev,
Deleted breakpoint 1 at /scratch/07169/wgl/adjoint/python/Main_no_matrix.py:61
Uncaught exception. Entering post mortem debugging
Running 'cont' or 'step' will restart the program
> /scratch/07169/wgl/adjoint/python/Main_no_matrix.py(99)errorIndicator()
-> residual = u_fine[n] - forwardFn(u_fine[:n], t_fine[:n], dt_fine[n - 1])
Post mortem debugger finished. The /scratch/07169/wgl/adjoint/python/Main_no_matrix.py will be restarted
> /scratch/07169/wgl/adjoint/python/Main_no_matrix.py(1)<module>()
-> import os
Traceback (most recent call last):
  File "/opt/apps/intel19/python3/3.9.7/lib/python3.9/pdb.py", line 1723, in main
    pdb._runscript(mainpyfile)
  File "/opt/apps/intel19/python3/3.9.7/lib/python3.9/pdb.py", line 1583, in _runscript
    self.run(statement)
  File "/opt/apps/intel19/python3/3.9.7/lib/python3.9/bdb.py", line 580, in run
    exec(cmd, globals, locals)
  File "<string>", line 1, in <module>
  File "/scratch/07169/wgl/adjoint/python/Main_no_matrix.py", line 190, in <module>
    err = errorIndicator(u, v, dt, ref_factor)
  File "/scratch/07169/wgl/adjoint/python/Main_no_matrix.py", line 99, in errorIndicator
    residual = u_fine[n] - forwardFn(u_fine[:n], t_fine[:n], dt_fine[n - 1])
TypeError: forwardFn() missing 2 required positional arguments: 'params' and 'net'
Program interrupted. (Use 'cont' to resume).
--Call--
> /work/07169/wgl/ls6/PHO-ICES/adj-env/lib/python3.9/site-packages/jax/_src/source_info_util.py(185)current()
-> def current() -> SourceInfo:
Restarting /scratch/07169/wgl/adjoint/python/Main_no_matrix.py with arguments:
	
> /scratch/07169/wgl/adjoint/python/Main_no_matrix.py(1)<module>()
-> import os
Uncaught exception. Entering post mortem debugging
Running 'cont' or 'step' will restart the program
> /scratch/07169/wgl/adjoint/python/Main_no_matrix.py(1)<module>()
-> import os
Traceback (most recent call last):
  File "/opt/apps/intel19/python3/3.9.7/lib/python3.9/pdb.py", line 1723, in main
    pdb._runscript(mainpyfile)
  File "/opt/apps/intel19/python3/3.9.7/lib/python3.9/pdb.py", line 1583, in _runscript
    self.run(statement)
  File "/opt/apps/intel19/python3/3.9.7/lib/python3.9/bdb.py", line 580, in run
    exec(cmd, globals, locals)
  File "<string>", line 1, in <module>
  File "/scratch/07169/wgl/adjoint/python/Main_no_matrix.py", line 1, in <module>
    import os
TypeError: errorIndicator() missing 2 required positional arguments: 'params' and 'net'
Traceback (most recent call last):
  File "/opt/apps/intel19/python3/3.9.7/lib/python3.9/pdb.py", line 1723, in main
    pdb._runscript(mainpyfile)
  File "/opt/apps/intel19/python3/3.9.7/lib/python3.9/pdb.py", line 1583, in _runscript
    self.run(statement)
  File "/opt/apps/intel19/python3/3.9.7/lib/python3.9/bdb.py", line 580, in run
    exec(cmd, globals, locals)
  File "<string>", line 1, in <module>
  File "/scratch/07169/wgl/adjoint/python/Main_no_matrix.py", line 1, in <module>
    import os
TypeError: errorIndicator() missing 2 required positional arguments: 'params' and 'net'
During handling of the above exception, another exception occurred:
Traceback (most recent call last):
  File "/opt/apps/intel19/python3/3.9.7/lib/python3.9/runpy.py", line 197, in _run_module_as_main
    return _run_code(code, main_globals, None,
  File "/opt/apps/intel19/python3/3.9.7/lib/python3.9/runpy.py", line 87, in _run_code
    exec(code, run_globals)
  File "/opt/apps/intel19/python3/3.9.7/lib/python3.9/pdb.py", line 1750, in <module>
    pdb.main()
  File "/opt/apps/intel19/python3/3.9.7/lib/python3.9/pdb.py", line 1723, in main
    pdb._runscript(mainpyfile)
  File "/opt/apps/intel19/python3/3.9.7/lib/python3.9/pdb.py", line 357, in interaction
    self._cmdloop()
  File "/opt/apps/intel19/python3/3.9.7/lib/python3.9/pdb.py", line 322, in _cmdloop
    self.cmdloop()
  File "/opt/apps/intel19/python3/3.9.7/lib/python3.9/cmd.py", line 138, in cmdloop
    stop = self.onecmd(line)
  File "/opt/apps/intel19/python3/3.9.7/lib/python3.9/pdb.py", line 422, in onecmd
    return cmd.Cmd.onecmd(self, line)
  File "/opt/apps/intel19/python3/3.9.7/lib/python3.9/cmd.py", line 217, in onecmd
    return func(arg)
  File "/opt/apps/intel19/python3/3.9.7/lib/python3.9/pdb.py", line 1036, in do_run
    raise Restart
pdb.Restart